<?xml version="1.0" encoding="utf-8"?>
<robot name="yunjing_robot" xmlns:xacro="http://www.ros.org/wiki/xacro">

  <link name="base">
    <inertial>
      <mass value="1"/>
      <origin rpy="0 0 0" xyz="0 0 0"/>
      <inertia ixx="0.166667" ixy="0" ixz="0" iyy="0.166667" iyz="0" izz="0.166667"/>
    </inertial>
    <visual>
      <origin rpy="0 0 0" xyz="0 0 1"/>
      <geometry>
        <box size="2 3 1"/>
      </geometry>
    </visual>
    <collision>
      <origin rpy="0 0 0" xyz="0 0 1"/>
      <geometry>
        <box size="2 3 1"/>
      </geometry>
    </collision>
  </link>

  <link name="link_left">
    <inertial>
      <mass value="1"/>
      <origin rpy="0 0 0" xyz="0 0 0"/>
      <inertia ixx="0.166667" ixy="0" ixz="0" iyy="0.166667" iyz="0" izz="0.166667"/>
    </inertial>
    <visual>
      <origin rpy="0 0 0" xyz="1 0 0"/>
      <geometry>
        <box size="2 0.2 0.2"/>
      </geometry>
    </visual>
    <collision>
      <origin rpy="0 0 0" xyz="1 0 0"/>
      <geometry>
        <box size="2 0.2 0.2"/>
      </geometry>
    </collision>
    <!-- different from both,why? -->
    <!-- <collision>
      <origin rpy="0 0 0" xyz="1 0 0"/>
      <geometry>
        <box size="2 0.2 0.2"/>
      </geometry>
    </collision> -->
  </link>

    <link name="link_right">
    <inertial>
      <mass value="1"/>
      <origin rpy="0 0 0" xyz="0 0 0"/>
      <inertia ixx="0.166667" ixy="0" ixz="0" iyy="0.166667" iyz="0" izz="0.166667"/>
    </inertial>
    <visual>
      <origin rpy="0 0 0" xyz="1 0 0"/>
      <geometry>
        <box size="2 0.2 0.2"/>
      </geometry>
    </visual>
    <collision>
      <origin rpy="0 0 0" xyz="1 0 0"/>
      <geometry>
        <box size="2 0.2 0.2"/>
      </geometry>
    </collision>
  </link>

  <link name="link_lf_fix">
    <inertial>
      <mass value="1"/>
      <origin rpy="0 0 0" xyz="0 0 0"/>
      <inertia ixx="0.145833" ixy="0" ixz="0" iyy="0.145833" iyz="0" izz="0.125"/>
    </inertial>
    <collision>
      <origin rpy="0 0 0" xyz="0 0 0"/>
      <geometry>
        <cylinder length="0.25" radius="0.3"/>
      </geometry>
    </collision>
    <visual>
      <origin rpy="0 0 0" xyz="0 0 0"/>
      <geometry>
        <cylinder length="0.25" radius="0.3"/>
      </geometry>
    </visual>
  </link>
  <link name="link_lf_rev">
    <inertial>
      <mass value="1"/>
      <origin rpy="0 0 0" xyz="0 0 0"/>
      <inertia ixx="0.145833" ixy="0" ixz="0" iyy="0.145833" iyz="0" izz="0.125"/>
    </inertial>
    <collision name="unit_box__collision">
      <origin rpy="0 0 0" xyz="0 0 0"/>
      <geometry>
        <cylinder length="0.2" radius="0.4"/>
      </geometry>
    </collision>
    <visual name="unit_box__visual">
      <origin rpy="0 0 0" xyz="0 0 0"/>
      <geometry>
        <cylinder length="0.2" radius="0.4"/>
      </geometry>
    </visual>
  </link>

  <link name="link_lb_fix">
    <inertial>
      <mass value="1"/>
      <origin rpy="0 0 0" xyz="0 0 0"/>
      <inertia ixx="0.145833" ixy="0" ixz="0" iyy="0.145833" iyz="0" izz="0.125"/>
    </inertial>
    <collision name="unit_box__collision">
      <origin rpy="0 0 0" xyz="0 0 0"/>
      <geometry>
        <cylinder length="0.25" radius="0.3"/>
      </geometry>
    </collision>
    <visual name="unit_box__visual">
      <origin rpy="0 0 0" xyz="0 0 0"/>
      <geometry>
        <cylinder length="0.25" radius="0.3"/>
      </geometry>
    </visual>
  </link>
  <link name="link_lb_rev">
    <inertial>
      <mass value="1"/>
      <origin rpy="0 0 0" xyz="0 0 0"/>
      <inertia ixx="0.145833" ixy="0" ixz="0" iyy="0.145833" iyz="0" izz="0.125"/>
    </inertial>
    <collision name="unit_box__collision">
      <origin rpy="0 0 0" xyz="0 0 0"/>
      <geometry>
        <cylinder length="0.2" radius="0.4"/>
      </geometry>
    </collision>
    <visual name="unit_box__visual">
      <origin rpy="0 0 0" xyz="0 0 0"/>
      <geometry>
        <cylinder length="0.2" radius="0.4"/>
      </geometry>
    </visual>
  </link>

  <link name="link_rf_fix">
    <inertial>
      <mass value="1"/>
      <origin rpy="0 0 0" xyz="0 0 0"/>
      <inertia ixx="0.145833" ixy="0" ixz="0" iyy="0.145833" iyz="0" izz="0.125"/>
    </inertial>
    <collision name="unit_box__collision">
      <origin rpy="0 0 0" xyz="0   0   0.02"/>
      <geometry>
        <cylinder length="0.25" radius="0.3"/>
      </geometry>
    </collision>
    <visual name="unit_box__visual">
      <origin rpy="0 0 0" xyz="0   0   0.02"/>
      <geometry>
        <cylinder length="0.25" radius="0.3"/>
      </geometry>
    </visual>
  </link>
  <link name="link_rf_rev">
    <inertial>
      <mass value="1"/>
      <origin rpy="0 0 0" xyz="0 0 0"/>
      <inertia ixx="0.145833" ixy="0" ixz="0" iyy="0.145833" iyz="0" izz="0.125"/>
    </inertial>
    <collision name="unit_box__collision">
      <origin rpy="0 0 0" xyz="0 0 0"/>
      <geometry>
        <cylinder length="0.2" radius="0.4"/>
      </geometry>
    </collision>
    <visual name="unit_box__visual">
      <origin rpy="0 0 0" xyz="0 0 0"/>
      <geometry>
        <cylinder length="0.2" radius="0.4"/>
      </geometry>
    </visual>
  </link>

  <link name="link_rb_fix">
    <inertial>
      <mass value="1"/>
      <origin rpy="0 0 0" xyz="0 0 0"/>
      <inertia ixx="0.145833" ixy="0" ixz="0" iyy="0.145833" iyz="0" izz="0.125"/>
    </inertial>
    <collision name="unit_box__collision">
      <origin rpy="0 0 0" xyz="0 0 0"/>
      <geometry>
        <cylinder length="0.25" radius="0.3"/>
      </geometry>
    </collision>
    <visual name="unit_box__visual">
      <origin rpy="0 0 0" xyz="0 0 0"/>
      <geometry>
        <cylinder length="0.25" radius="0.3"/>
      </geometry>
    </visual>
  </link>
  <link name="link_rb_rev">
    <inertial>
      <mass value="1"/>
      <origin rpy="0 0 0" xyz="0 0 0"/>
      <inertia ixx="0.145833" ixy="0" ixz="0" iyy="0.145833" iyz="0" izz="0.125"/>
    </inertial>
    <collision name="unit_box__collision">
      <origin rpy="0 0 0" xyz="0 0 0"/>
      <geometry>
        <cylinder length="0.2" radius="0.4"/>
      </geometry>
    </collision>
    <visual name="unit_box__visual">
      <origin rpy="0 0 0" xyz="0 0 0"/>
      <geometry>
        <cylinder length="0.2" radius="0.4"/>
      </geometry>
    </visual>
  </link>



  <joint name="joint_left" type="revolute">
    <origin rpy="0 0 0" xyz="-1  -1.5  1.25"/>
    <parent link="base"/>
    <child link="link_left"/>
    <axis xyz="0 0 -1"/>
    <limit lower="0" upper="1.7453" effort="-1" velocity="0"/>
  </joint>

  <joint name="joint_right" type="revolute">
    <origin rpy="0 0 0" xyz="-1  1.5  1.25"/>
    <parent link="base"/>
    <child link="link_right"/>
    <axis xyz="0 0 1"/>
    <limit lower="0" upper="1.7453" effort="-1" velocity="0"/>
  </joint>

  <joint name="joint_lf_fix" type="prismatic">
    <parent link="base"/>
    <child link="link_lf_fix"/>
    <origin rpy="1.57078 0 0" xyz="0.5 1.5 0.5"/>
    <axis xyz="0 1 0"/>
    <limit effort="-1.0" lower="-0.3" upper="0.3" velocity="-1.0"/>
  </joint>
  <joint name="joint_lf_rev" type="revolute">
    <parent link="link_lf_fix"/>
    <child link="link_lf_rev"/>
    <origin rpy="1.e-05 0.e+00 0.e+00" xyz="0 0 0"/>
    <axis xyz="0 0 1"/>
    <limit effort="-1.0" lower="-1e30" upper="1e30" velocity="-1.0"/>
  </joint>

  <joint name="joint_lb_fix" type="prismatic">
    <parent link="base"/>
    <child link="link_lb_fix"/>
    <origin rpy="1.57078 0      0" xyz="-0.5  1.5  0.5"/>
    <axis xyz="0 1 0"/>
    <limit effort="-1.0" lower="-0.3" upper="0.3" velocity="-1.0"/>
  </joint>
  <joint name="joint_lb_rev" type="revolute">
    <parent link="link_lb_fix"/>
    <child link="link_lb_rev"/>
    <origin rpy="1.e-05 0.e+00 0.e+00" xyz="0 0 0"/>
    <axis xyz="0 0 1"/>
    <limit effort="-1.0" lower="-1e30" upper="1e30" velocity="-1.0"/>
  </joint>

  <joint name="joint_rf_fix" type="prismatic">
    <parent link="base"/>
    <child link="link_rf_fix"/>
    <origin rpy="1.57079 0      0" xyz="0.5  -1.48  0.5"/>
    <axis xyz="0  1 0"/>
    <limit effort="-1.0" lower="-0.3" upper="0.3" velocity="-1.0"/>
  </joint>
  <joint name="joint_rf_rev" type="revolute">
    <parent link="link_rf_fix"/>
    <child link="link_rf_rev"/>
    <origin rpy="1.e-05 0.e+00 0.e+00" xyz="0   0   0.02"/>
    <axis xyz="0 0  -1"/>
    <limit effort="-1.0" lower="-1e30" upper="1e30" velocity="-1.0"/>
  </joint>


  <joint name="joint_rb_fix" type="prismatic">
    <parent link="base"/>
    <child link="link_rb_fix"/>
    <origin rpy="1.57079 0      0" xyz="-0.5 -1.5  0.5"/>
    <axis xyz="0  1 0"/>
    <limit effort="-1.0" lower="-0.3" upper="0.3" velocity="-1.0"/>
  </joint>
  <joint name="joint_rb_rev" type="revolute">
    <parent link="link_rb_fix"/>
    <child link="link_rb_rev"/>
    <origin rpy="1.e-05 0.e+00 0.e+00" xyz="0 0 0"/>
    <axis xyz="0 0  -1"/>
    <limit effort="-1.0" lower="-1e30" upper="  1e30" velocity="-1.0"/>
  </joint>


  

</robot>